 * Running on http://127.0.0.1:5000/ (Press CTRL+C to quit)
Traceback (most recent call last):
  File "server.py", line 133, in <module>
    app.run()
  File "/Users/zeigerc/env/backend/venv/lib/python2.7/site-packages/flask/app.py", line 772, in run
    run_simple(host, port, self, **options)
  File "/Users/zeigerc/env/backend/venv/lib/python2.7/site-packages/werkzeug/serving.py", line 618, in run_simple
    test_socket.bind((hostname, port))
  File "/System/Library/Frameworks/Python.framework/Versions/2.7/lib/python2.7/socket.py", line 224, in meth
    return getattr(self._sock,name)(*args)
socket.error: [Errno 48] Address already in use
